<?xml version="1.0"?>
<robot name="robot">
    <material name="grey">
        <color rgba="0.7 0.7 0.7 1"/>
    </material>

    <material name="green">
        <color rgba="0 0.6 0 1"/>
    </material>

    <material name="white">
        <color rgba="1 1 1 1"/>
    </material>

    <link name="base_footprint"/>

    <link name="base_link">
        <visual>
            <geometry>
                <box size="0.4 0.4 0.5"/>
            </geometry>    
            <origin xyz="0 0 0.25" rpy="0 0 0"/>
            <material name="grey"/>
        </visual>
    </link>

    <link name="left_wheel">
        <visual>
            <geometry>
                <cylinder radius="0.2" length="0.05"/>
            </geometry>
            <origin xyz="0 0 0" rpy="1.57 0 0"/>
            <material name="green"/>
        </visual>
    </link>

    <link name="right_wheel">
        <visual>
            <geometry>
                <cylinder radius="0.2" length="0.05"/>
            </geometry>
            <origin xyz="0 0 0" rpy="1.57 0 0"/>
            <material name="green"/>
        </visual>
    </link>

    <joint name="base_joint" type="fixed">
    <parent link="base_footprint"/>
    <child link="base_link"/>
    <origin xyz="0 0 0.2" rpy="0 0 0"/>
    </joint>


    <joint name="base_left_joint" type="continuous">
        <parent link="base_link"/>
        <child link="left_wheel"/>
        <origin xyz="0 0.225 0" rpy="0 0 0"/>
        <axis xyz="0 1 0.0"/>
    </joint>

    <joint name="base_right_joint" type="continuous">
        <parent link="base_link"/>
        <child link="right_wheel"/>
        <origin xyz="0 -0.225 0" rpy="0 0 0"/>
        <axis xyz="0 1 0.0"/>
    </joint>

</robot>